Workbook

Sheet Form Responses 3
A1: Timestamp | B1: Email Address | C1: What is your current Grade/Year level? | D1: On an average visit, exactly how many minutes do you usually spend inside the school library? (Please give your best estimate as a single number, not a range. For example: 45, not 30-60). | E1: What is your primary reason for visiting the library? (Check one) | F1: Minutes (cleaned)
A2: 46301.789 | B2: lorenzokylecainglet1300@gmail.com | C2: 2nd year | D2: 45 | E2: Studying / Doing Homework, Using computers / printing | F2: =D2 -> 45
A3: 46301.794 | B3: angelonavarro25136@gmail.com | C3: 2nd Year | D3: 13 | E3: Resting / Waiting for next class | F3: =D3 -> 13
A4: 46302.026 | B4: cielom884@gmail.com | C4: 4th Year | D4: 60 | E4: Studying / Doing Homework, Group Meetings / Projects, Resting / Waiting for next class, Using computers / printing | F4: =D4 -> 60
A5: 46302.628 | B5: bembombales121@gmail.com | C5: 1st year | D5: 1 | E5: Resting / Waiting for next class | F5: =D5 -> 1
A6: 46302.796 | B6: eriannepineda@gmail.com | C6: 4th year | D6: 60 | E6: Studying / Doing Homework, Using computers / printing | F6: =D6 -> 60
A7: 46302.861 | B7: arviesinocruz28@gmail.com | C7: 4th Year | D7: 120 mins | E7: Studying / Doing Homework, Research / Borrowing Books, Group Meetings / Projects, Resting / Waiting for next class, Using computers / printing | F7: 120
A8: 46302.863 | B8: gwen1214.genosa@gmail.com | C8: 4th yr | D8: 2-3 hrs | E8: Studying / Doing Homework, Group Meetings / Projects, Resting / Waiting for next class, Using computers / printing | F8: 150
A9: 46302.863 | B9: srh.sphg@gmail.com | C9: 4th year | D9: 30 | E9: Studying / Doing Homework, Research / Borrowing Books, Resting / Waiting for next class | F9: =D9 -> 30
A10: 46302.865 | B10: lebronjames.pileo03@gmail.com | C10: 3rd year | D10: 20-40 | E10: Studying / Doing Homework, Resting / Waiting for next class, Using computers / printing | F10: 30
A11: 46302.867 | B11: adreinnezharyhalle@gmail.com | C11: 4th year | D11: 300 | E11: Studying / Doing Homework, Resting / Waiting for next class | F11: =D11 -> 300
A12: 46302.944 | B12: 2025044981@feu.edu.ph | C12: 1st Year | D12: 60 | E12: Studying / Doing Homework, Group Meetings / Projects, Resting / Waiting for next class | F12: =D12 -> 60
A13: 46302.944 | B13: 2024038791@feu.edu.ph | C13: 3rd year | D13: 150 minutes | E13: Studying / Doing Homework | F13: 150
A14: 46302.951 | B14: ruedajoyce826@gmail.com | C14: Year 4 | D14: 5 mins | E14: Using computers / printing | F14: 5
A15: 46302.984 | B15: ericka.ordizo@gmail.com | C15: First year | D15: 20 | E15: Resting / Waiting for next class | F15: =D15 -> 20
A16: 46303.034 | B16: 2025041521@feu.edu.ph | C16: 2nd Year | D16: 30 mins | E16: Studying / Doing Homework, Using computers / printing | F16: 30
A17: 46303.435 | B17: borelatteyy@gmail.com | C17: freshman | D17: 30 | E17: Resting / Waiting for next class, Using computers / printing | F17: =D17 -> 30
A18: 46303.571 | B18: mjbacojo04@gmail.com | C18: 3 | D18: 30 | E18: Resting / Waiting for next class | F18: =D18 -> 30
A19: 46303.594 | B19: caninorhea@gmail.com | C19: 3rd year | D19: 30mins | E19: Group Meetings / Projects | F19: 30
A20: 46303.595 | B20: lancenathanielorlina@gmail.com | C20: 1st year | D20: 30 | E20: Resting / Waiting for next class | F20: =D20 -> 30
A21: 46303.595 | B21: romerogladimir01@gmail.com | C21: 1st Year | D21: 30 | E21: Studying / Doing Homework, Resting / Waiting for next class, Using computers / printing | F21: =D21 -> 30
A22: 46303.641 | B22: 2025013801@feu.edu.ph | C22: 2nd Year | D22: 30 minutes | E22: Studying / Doing Homework | F22: 30
A23: 46303.655 | B23: 2025003841@feu.edu.ph | C23: 2nd Year | D23: 60 | E23: Studying / Doing Homework, Group Meetings / Projects, Resting / Waiting for next class | F23: =D23 -> 60
A24: 46303.707 | B24: dongjing06_39@gmail.com | C24: 3 | D24: 30 | E24: Studying / Doing Homework, Resting / Waiting for next class | F24: =D24 -> 30
A25: 46303.745 | B25: lopez.iandee2004@gmail.com | C25: 4th year | D25: 60 | E25: Studying / Doing Homework, Research / Borrowing Books, Using computers / printing | F25: =D25 -> 60
A26: 46303.751 | B26: cantelajsg@gmail.com | C26: 4th year | D26: 30 | E26: Resting / Waiting for next class, Using computers / printing | F26: =D26 -> 30
A27: 46303.751 | B27: adenalems@gmail.com | C27: 2nd year | D27: 40 | E27: Resting / Waiting for next class, Using computers / printing | F27: =D27 -> 40
A28: 46303.757 | B28: jerishjohnvelarde@gmail.com | C28: 2 | D28: 10 | E28: Group Meetings / Projects, Using computers / printing | F28: =D28 -> 10
A29: 46303.757 | B29: venisseoliva@gmail.com | C29: 4th | D29: 1 hour | E29: Studying / Doing Homework | F29: 60
A30: 46303.757 | B30: paraguyayuri@gmail.com | C30: 1st year college | D30: 90 minutes | E30: Studying / Doing Homework, Research / Borrowing Books, Group Meetings / Projects, Resting / Waiting for next class | F30: 90
A31: 46303.758 | B31: michaelprocopiovalte16@gmail.com | C31: Year 3 | D31: 120 | E31: Studying / Doing Homework, Research / Borrowing Books, Resting / Waiting for next class | F31: =D31 -> 120
A32: 46303.762 | B32: jj7ssnllanllo@gmail.com | C32: 3rd yr | D32: 60 minutes | E32: Using computers / printing | F32: 60
A33: 46303.782 | B33: tupasaldrin27@gmail.com | C33: 4th year | D33: 240 | E33: Using computers / printing | F33: =D33 -> 240
A34: 46303.792 | B34: jordanlegayada@gmail.com | C34: 4th year | D34: 180 | E34: Resting / Waiting for next class | F34: =D34 -> 180
A35: 46303.8 | B35: 2023036671@feu.edu.ph | C35: 4th year | D35: 180 | E35: Using computers / printing | F35: =D35 -> 180
A36: 46303.8 | B36: 2023037871@feu.edu.ph | C36: 4th | D36: 160 | E36: Resting / Waiting for next class | F36: =D36 -> 160
A37: 46303.801 | B37: happycork@gmail.com | C37: 3rd year | D37: 130 | E37: Resting / Waiting for next class | F37: =D37 -> 130
A38: 46303.801 | B38: 2023037181@feu.edu.ph | C38: 4th year | D38: 50 | E38: Studying / Doing Homework, Resting / Waiting for next class | F38: =D38 -> 50
A39: 46303.801 | B39: danielmiles@gmail.com | C39: 4th year | D39: 150 | E39: Group Meetings / Projects | F39: =D39 -> 150
A40: 46303.801 | B40: lancegodfrey@gmail.com | C40: 4th | D40: 80 | E40: Research / Borrowing Books | F40: =D40 -> 80
...

Sheet Sheet1
A1: Respondent ID | B1: Time Spent (minutes) | C1: Primary Reason | D1: Grade/Year Level | F1: Statistics | G1: Value | I1: Bin (Minutes up to...) | J1: Frequency
A2: 1 | B2: 60 | C2: stduying | D2: 4th | F2: Mean (μ) | G2: =IFERROR(AVERAGE(B2:B51), "") -> 93.32 | I2: 15 | J2: =COUNTIFS($B$2:$B$51,"<="&I2) -> 1
A3: 2 | B3: 60 | C3: resting | D3: 4th | F3: Standard Dev (σ) | G3: =IFERROR(_xlfn.STDEV.S(B2:B51), "") -> 72.274545 | I3: 30 | J3: =COUNTIFS($B$2:$B$51,">"&I2,$B$2:$B$51,"<="&I3) -> 14
A4: 3 | B4: 60 | C4: resting | D4: 4th | F4: Sample Size (n) | G4: =COUNT(B2:B51) -> 50 | I4: 45 | J4: =COUNTIFS($B$2:$B$51,">"&I3,$B$2:$B$51,"<="&I4) -> 3
A5: 4 | B5: 30 | C5: stduying | D5: 4th | I5: 60 | J5: =COUNTIFS($B$2:$B$51,">"&I4,$B$2:$B$51,"<="&I5) -> 11
A6: 5 | B6: 30 | C6: stduying | D6: 4th | F6: Empirical Rule Intervals | I6: 120 | J6: =COUNTIFS($B$2:$B$51,">"&I5,$B$2:$B$51,"<="&I6) -> 5
A7: 6 | B7: 60 | C7: stduying | D7: 4th | F7: +1σ (68% limit) | G7: =IF(G4>1, G2+G3, "") -> 165.59454 | I7: 180 | J7: =COUNTIFS($B$2:$B$51,">"&I6,$B$2:$B$51,"<="&I7) -> 12
A8: 7 | B8: 150 | C8: resting | D8: 3rd | F8: -1σ (68% limit) | G8: =IF(G4>1, G2-G3, "") -> 21.045455 | I8: 240 | J8: =COUNTIFS($B$2:$B$51,">"&I7,$B$2:$B$51,"<="&I8) -> 1
A9: 8 | B9: 300 | C9: resting | D9: 3rd | F9: +2σ (95% limit) | G9: =IF(G4>1, G2+(2*G3), "") -> 237.86909 | I9: 300 | J9: =COUNTIFS($B$2:$B$51,">"&I8,$B$2:$B$51,"<="&I9) -> 3
A10: 9 | B10: 50 | C10: using computer | D10: 3rd | F10: -2σ (95% limit) | G10: =IF(G4>1, G2-(2*G3), "") -> -51.229089 | I10: Total | J10: =SUM(J2:J9) -> 50
A11: 10 | B11: 120 | C11: using computer | D11: 2nd | F11: +3σ (99.7% limit) | G11: =IF(G4>1, G2+(3*G3), "") -> 310.14363
A12: 11 | B12: 45 | C12: using computer | D12: 2nd | F12: -3σ (99.7% limit) | G12: =IF(G4>1, G2-(3*G3), "") -> -123.50363
A13: 12 | B13: 30 | C13: resting | D13: 2nd
A14: 13 | B14: 33 | C14: resting | D14: 1st
A15: 14 | B15: 55 | C15: studying | D15: 1st
A16: 15 | B16: 180 | C16: resting | D16: 1st
A17: 16 | B17: 20 | C17: studying | D17: 1st
A18: 17 | B18: 30 | C18: resting | D18: 3rd
A19: 18 | B19: 30 | C19: resting | D19: 3rd
A20: 19 | B20: 30 | C20: group meeting | D20: 1st
A21: 20 | B21: 30 | C21: resting | D21: 1st
A22: 21 | B22: 30 | C22: studying | D22: 2nd
A23: 22 | B23: 30 | C23: resting | D23: 2nd
A24: 23 | B24: 30 | C24: studying | D24: 2nd
... A51: 50 | B51: 170 | C51: using computer | D51: 2nd

Sheet Charts
A1: Library Visit Duration Survey – Charts
A2: Source: Sheet1 (all tables below are formulas, so charts update when Sheet1 changes).
A4: Minutes | B4: Respondents | D4: Primary reason | E4: Respondents | G4: Year level | H4: Respondents | I4: Avg minutes | K4: Primary reason | L4: Avg minutes
A5: 0–15 | B5: =COUNTIFS(Sheet1!$B$2:$B$51,">0",Sheet1!$B$2:$B$51,"<=15") -> 1 | D5: Studying | E5: =COUNTIF(Sheet1!$C$2:$C$51,"studying")+COUNTIF(Sheet1!$C$2:$C$51,"stduying") -> 14 | G5: 1st | H5: =COUNTIF(Sheet1!$D$2:$D$51,G5) -> 10 | I5: =IFERROR(AVERAGEIF(Sheet1!$D$2:$D$51,G5,Sheet1!$B$2:$B$51),0) -> 78.8 | K5: Studying | L5: =(SUMIF(Sheet1!$C$2:$C$51,"studying",Sheet1!$B$2:$B$51)+SUMIF(Sheet1!$C$2:$C$51,"stduying",Sheet1!$B$2:$B$51))/E5 -> 63.928571
A6: 16–30 | B6: =COUNTIFS(Sheet1!$B$2:$B$51,">15",Sheet1!$B$2:$B$51,"<=30") -> 14 | D6: Resting | E6: =COUNTIF(Sheet1!$C$2:$C$51,"resting") -> 21 | G6: 2nd | H6: =COUNTIF(Sheet1!$D$2:$D$51,G6) -> 10 | I6: =IFERROR(AVERAGEIF(Sheet1!$D$2:$D$51,G6,Sheet1!$B$2:$B$51),0) -> 67.3 | K6: Resting | L6: =SUMIF(Sheet1!$C$2:$C$51,"resting",Sheet1!$B$2:$B$51)/E6 -> 110.28571
A7: 31–60 | B7: =COUNTIFS(Sheet1!$B$2:$B$51,">30",Sheet1!$B$2:$B$51,"<=60") -> 14 | D7: Using computer | E7: =COUNTIF(Sheet1!$C$2:$C$51,"using computer") -> 11 | G7: 3rd | H7: =COUNTIF(Sheet1!$D$2:$D$51,G7) -> 14 | I7: =IFERROR(AVERAGEIF(Sheet1!$D$2:$D$51,G7,Sheet1!$B$2:$B$51),0) -> 108.21429 | K7: Using computer | L7: =SUMIF(Sheet1!$C$2:$C$51,"using computer",Sheet1!$B$2:$B$51)/E7 -> 115.90909
A8: 61–120 | B8: =COUNTIFS(Sheet1!$B$2:$B$51,">60",Sheet1!$B$2:$B$51,"<=120") -> 5 | D8: Group meeting | E8: =COUNTIF(Sheet1!$C$2:$C$51,"group meeting") -> 3 | G8: 4th | H8: =COUNTIF(Sheet1!$D$2:$D$51,G8) -> 16 | I8: =IFERROR(AVERAGEIF(Sheet1!$D$2:$D$51,G8,Sheet1!$B$2:$B$51),0) -> 105.625 | K8: Group meeting | L8: =SUMIF(Sheet1!$C$2:$C$51,"group meeting",Sheet1!$B$2:$B$51)/E8 -> 40
A9: 121–180 | B9: =COUNTIFS(Sheet1!$B$2:$B$51,">120",Sheet1!$B$2:$B$51,"<=180") -> 12 | D9: Research | E9: =COUNTIF(Sheet1!$C$2:$C$51,"research") -> 1 | K9: Research | L9: =SUMIF(Sheet1!$C$2:$C$51,"research",Sheet1!$B$2:$B$51)/E9 -> 60
A10: 181–240 | B10: =COUNTIFS(Sheet1!$B$2:$B$51,">180",Sheet1!$B$2:$B$51,"<=240") -> 1 | D10: Total | E10: =SUM(E5:E9) -> 50
A11: 241–300 | B11: =COUNTIFS(Sheet1!$B$2:$B$51,">240",Sheet1!$B$2:$B$51,"<=300") -> 3
A12: Total | B12: =SUM(B5:B11) -> 50
A14: Note: "stduying" (typo) in Sheet1 column C is counted as Studying.
